Workbook

Sheet START HERE
A1: OPERATION FULL STACK — Kerala Edition
A2: Your companion workbook. Works with the HTML roadmap (Full-Stack-Roadmap-Kerala.html). Tick, log, apply, repeat.
B4: Your mission | C4: Move from frontend intern → full-stack developer (MERN + TypeScript, with Python and Power BI as multipliers) and land a role in Kerala, South India, or a major Indian IT hub. Target window: 32 weeks.
B6: How to use this workbook
B7: DASHBOARD | C7: Live progress. Formulas update automatically as you fill the other tabs. Look here every Sunday.
B8: STUDY TRACKER | C8: 148 topic checkpoints across 9 seasons. Set Status = Done when you can explain it without notes.
B9: WEEKLY LOG | C9: 32 weeks pre-dated from Mon 19 Oct 2026. Log hours, DSA count, wins and blockers every week.
B10: PROJECTS | C10: The 5-project ladder with milestone checklists. A project is 'done' only when it is deployed.
B11: DSA LOG | C11: 150 rows pre-filled with 20 patterns + 30 starter problems. 45 minutes a day from week 3.
B12: JOB APPLICATIONS | C12: Every application, referral, status and follow-up date. Never lose a lead.
B13: INTERVIEW PREP | C13: 40 real fresher questions. Write your answer in your own words, rate confidence, revise weekly.
B14: RESOURCES | C14: All verified YouTube courses, docs, PDF cheat sheets and Kerala job boards in one place.
B15: CHEAT SHEET | C15: Git commands, VS Code shortcuts, JS array methods — the printable stuff.
B16: SKILLS | C16: Rate yourself now vs target. Evidence column = which project proves it.
B18: The week
B19: Mon–Thu | C19: 6 hours — Theory → code-along → build-alone → DSA → log
B20: Friday | C20: Project day — 6+ hours of pure building. No new videos. Ship something.
B21: Saturday | C21: Recovery + 1h — Rest, family, gym. Optional: 1 hour of job-portal browsing.
B22: Sunday | C22: Recovery — Zero study guilt. Burnout is the real final boss.
B24: Five laws
B25: • | C25: 70/30 rule: 70% building, 30% watching. Every video ends with the tab closed.
B26: • | C26: One boss per season: no new phase until the deliverable is deployed.
B27: • | C27: Daily commit: a green GitHub square is proof of life.
B28: • | C28: 45 min DSA daily from week 3 — not 5-hour Sunday marathons.
B29: • | C29: One rest day. Burnout is the real final boss.
B31: Legend
B32: Not started | C32: No work yet
B33: In progress | C33: Actively learning / building
B34: Done | C34: You can explain and rebuild it
B35: Revise | C35: Done once, needs a second pass

Sheet DASHBOARD
A1: DASHBOARD
A2: Everything below is formula-driven. Fill the other tabs and this updates itself.
B3: =IFERROR(COUNTIF('STUDY TRACKER'!$H$4:$H$151,"Done")/COUNTA('STUDY TRACKER'!$C$4:$C$151),0) | D3: =SUM('WEEKLY LOG'!$E$4:$E$35) | F3: =COUNTIF('DSA LOG'!$F$4:$F$153,"Solved") | H3: =COUNTA('JOB APPLICATIONS'!$B$4:$B$203)
B4: STUDY PROGRESS | D4: HOURS LOGGED | F4: DSA PROBLEMS SOLVED | H4: APPLICATIONS SENT
B7: =COUNTIF('JOB APPLICATIONS'!$G$4:$G$203,"Interview")+COUNTIF('JOB APPLICATIONS'!$G$4:$G$203,"Offer") | D7: =COUNTIF('PROJECTS'!$I$4:$I$8,"Deployed") | F7: =COUNTIF('STUDY TRACKER'!$H$4:$H$151,"In progress") | H7: =IFERROR(ROUND(AVERAGEIF('STUDY TRACKER'!$I$4:$I$151,">0"),1),0)
B8: INTERVIEWS | D8: PROJECTS DEPLOYED | F8: TOPICS IN PROGRESS | H8: AVG CONFIDENCE
B10: SEASON PROGRESS
A11: Season | B11: Topics done | C11: Total | D11: % complete | E11: Planned hrs | F11: Hours logged*
B12: 01 🎮 Setup, Git & HTML/CSS Pro | C12: =COUNTIFS('STUDY TRACKER'!$A$4:$A$151,$B12,'STUDY TRACKER'!$H$4:$H$151,"Done") | D12: =COUNTIF('STUDY TRACKER'!$A$4:$A$151,$B12) | E12: =IFERROR(C12/D12,0) | F12: 24 | G12: 24
B13: 02 ⚡ JavaScript Deep Dive | C13: =COUNTIFS('STUDY TRACKER'!$A$4:$A$151,$B13,'STUDY TRACKER'!$H$4:$H$151,"Done") | D13: =COUNTIF('STUDY TRACKER'!$A$4:$A$151,$B13) | E13: =IFERROR(C13/D13,0) | F13: 70 | G13: 70
B14: 03 🔥 React + TypeScript + Tailwind | C14: =COUNTIFS('STUDY TRACKER'!$A$4:$A$151,$B14,'STUDY TRACKER'!$H$4:$H$151,"Done") | D14: =COUNTIF('STUDY TRACKER'!$A$4:$A$151,$B14) | E14: =IFERROR(C14/D14,0) | F14: 80 | G14: 80
B15: 04 🏰 Node.js + Express + MongoDB | C15: =COUNTIFS('STUDY TRACKER'!$A$4:$A$151,$B15,'STUDY TRACKER'!$H$4:$H$151,"Done") | D15: =COUNTIF('STUDY TRACKER'!$A$4:$A$151,$B15) | E15: =IFERROR(C15/D15,0) | F15: 90 | G15: 90
B16: 05 🗺️ SQL + Python (Kerala JD insurance) | C16: =COUNTIFS('STUDY TRACKER'!$A$4:$A$151,$B16,'STUDY TRACKER'!$H$4:$H$151,"Done") | D16: =COUNTIF('STUDY TRACKER'!$A$4:$A$151,$B16) | E16: =IFERROR(C16/D16,0) | F16: 45 | G16: 45
B17: 06 🐉 Capstone + Docker + CI/CD | C17: =COUNTIFS('STUDY TRACKER'!$A$4:$A$151,$B17,'STUDY TRACKER'!$H$4:$H$151,"Done") | D17: =COUNTIF('STUDY TRACKER'!$A$4:$A$151,$B17) | E17: =IFERROR(C17/D17,0) | F17: 70 | G17: 70
B18: 07 🗡️ DSA & Problem Solving | C18: =COUNTIFS('STUDY TRACKER'!$A$4:$A$151,$B18,'STUDY TRACKER'!$H$4:$H$151,"Done") | D18: =COUNTIF('STUDY TRACKER'!$A$4:$A$151,$B18) | E18: =IFERROR(C18/D18,0) | F18: 40 | G18: 40
B19: 08 📊 Power BI + Analytics | C19: =COUNTIFS('STUDY TRACKER'!$A$4:$A$151,$B19,'STUDY TRACKER'!$H$4:$H$151,"Done") | D19: =COUNTIF('STUDY TRACKER'!$A$4:$A$151,$B19) | E19: =IFERROR(C19/D19,0) | F19: 30 | G19: 30
B20: 09 🏁 Portfolio, Resume & Offers | C20: =COUNTIFS('STUDY TRACKER'!$A$4:$A$151,$B20,'STUDY TRACKER'!$H$4:$H$151,"Done") | D20: =COUNTIF('STUDY TRACKER'!$A$4:$A$151,$B20) | E20: =IFERROR(C20/D20,0) | F20: 100 | G20: 100
B21: TOTAL | C21: =SUM(C12:C20) | D21: =SUM(D12:D20) | E21: =IFERROR(C21/D21,0) | F21: =SUM(F12:F20) | G21: =SUM(G12:G20)
B23: * Column G starts as planned hours — overwrite it with your real logged hours per season.
B25: THE GOAL
B26: ☐ Portfolio live | C26: Day 7
B27: ☐ 3 JavaScript projects deployed | C27: Day 30
B28: ☐ React + TypeScript project live | C28: Day 60
B29: ☐ Authenticated REST API deployed | C29: Day 90
B30: ☐ Capstone shipped with Docker + CI | C30: Day 120
B31: ☐ 100+ applications + 10 referrals | C31: Day 180
B32: ☐ Offer signed | C32: Day 210–240

Sheet STUDY TRACKER
A1: STUDY TRACKER
A2: One row per checkpoint. Status drives the dashboard. Planned hrs is a guide — log real hours in WEEKLY LOG.
A3: Season | B3: # | C3: Topic / checkpoint | D3: Main resource (see RESOURCES tab) | E3: Planned hrs | F3: Start date | G3: Done date | H3: Status | I3: Confidence 1–5 | J3: Revision date | K3: Notes / questions
A4: 01 🎮 Setup, Git & HTML/CSS Pro | B4: 1 | C4: Install VS Code + Prettier, ESLint, Live Server, GitLens, Error Lens | D4: Kunal Kushwaha — Complete Git and GitHub Tutorial | E4: 1.5 | H4: Not started | I4: 0
A5: 01 🎮 Setup, Git & HTML/CSS Pro | B5: 2 | C5: Install Node.js LTS · verify `node -v` and `npm -v` | E5: 1.5 | H5: Not started | I5: 0
A6: 01 🎮 Setup, Git & HTML/CSS Pro | B6: 3 | C6: Set Git user.name / user.email + add SSH key to GitHub | E6: 1.5 | H6: Not started | I6: 0
A7: 01 🎮 Setup, Git & HTML/CSS Pro | B7: 4 | C7: Create GitHub profile README + repo `learning-log` | E7: 1.5 | H7: Not started | I7: 0
A8: 01 🎮 Setup, Git & HTML/CSS Pro | B8: 5 | C8: Master the 15 daily Git commands (add, commit, branch, merge, push, pull, stash) | E8: 1.5 | H8: Not started | I8: 0
A9: 01 🎮 Setup, Git & HTML/CSS Pro | B9: 6 | C9: Open your first pull request (fix a typo in any open-source README) | E9: 1.5 | H9: Not started | I9: 0
A10: 01 🎮 Setup, Git & HTML/CSS Pro | B10: 7 | C10: Semantic HTML: header / nav / main / section / article / footer + forms | E10: 1.5 | H10: Not started | I10: 0
A11: 01 🎮 Setup, Git & HTML/CSS Pro | B11: 8 | C11: CSS box model, specificity, cascade, rem/em/clamp() | E11: 1.5 | H11: Not started | I11: 0
A12: 01 🎮 Setup, Git & HTML/CSS Pro | B12: 9 | C12: Flexbox: justify-content, align-items, gap, wrap | E12: 1.5 | H12: Not started | I12: 0
A13: 01 🎮 Setup, Git & HTML/CSS Pro | B13: 10 | C13: CSS Grid: auto-fit + minmax, grid-template-areas | E13: 1.5 | H13: Not started | I13: 0
A14: 01 🎮 Setup, Git & HTML/CSS Pro | B14: 11 | C14: Mobile-first media queries + fluid typography | E14: 1.5 | H14: Not started | I14: 0
A15: 01 🎮 Setup, Git & HTML/CSS Pro | B15: 12 | C15: CSS variables, transitions, hover & focus states | E15: 1.5 | H15: Not started | I15: 0
A16: 01 🎮 Setup, Git & HTML/CSS Pro | B16: 13 | C16: Accessibility: alt text, contrast, keyboard nav, focus rings | E16: 1.5 | H16: Not started | I16: 0
... A19: 01 🎮 Setup, Git & HTML/CSS Pro | B19: 16 | C19: Write a README with screenshots and the live link | E19: 1.5 | H19: Not started | I19: 0
A20: 02 ⚡ JavaScript Deep Dive | B20: 1 | C20: let / const / var, scope, temporal dead zone, hoisting | D20: SuperSimpleDev — JavaScript Tutorial Full Course – Beginner to Pro (2024) | E20: 3.9 | H20: Not started | I20: 0
A21: 02 ⚡ JavaScript Deep Dive | B21: 2 | C21: Functions, arrow functions, callbacks, pure functions | E21: 3.9 | H21: Not started | I21: 0
A22: 02 ⚡ JavaScript Deep Dive | B22: 3 | C22: Arrays: map, filter, reduce, find, some, every, sort | E22: 3.9 | H22: Not started | I22: 0
A23: 02 ⚡ JavaScript Deep Dive | B23: 4 | C23: Objects, destructuring, spread/rest, optional chaining | E23: 3.9 | H23: Not started | I23: 0
A24: 02 ⚡ JavaScript Deep Dive | B24: 5 | C24: DOM: querySelector, createElement, classList, events | E24: 3.9 | H24: Not started | I24: 0
A25: 02 ⚡ JavaScript Deep Dive | B25: 6 | C25: Event delegation + forms + preventDefault + validation | E25: 3.9 | H25: Not started | I25: 0
A26: 02 ⚡ JavaScript Deep Dive | B26: 7 | C26: ES modules (import / export) | E26: 3.9 | H26: Not started | I26: 0
A27: 02 ⚡ JavaScript Deep Dive | B27: 8 | C27: Promises: then / catch / finally | E27: 3.9 | H27: Not started | I27: 0
A28: 02 ⚡ JavaScript Deep Dive | B28: 9 | C28: async / await + try / catch + error handling | E28: 3.9 | H28: Not started | I28: 0
A29: 02 ⚡ JavaScript Deep Dive | B29: 10 | C29: fetch + REST + JSON + loading & error states | E29: 3.9 | H29: Not started | I29: 0
A30: 02 ⚡ JavaScript Deep Dive | B30: 11 | C30: localStorage / sessionStorage | E30: 3.9 | H30: Not started | I30: 0
A31: 02 ⚡ JavaScript Deep Dive | B31: 12 | C31: Closures, `this`, call / apply / bind | E31: 3.9 | H31: Not started | I31: 0
A32: 02 ⚡ JavaScript Deep Dive | B32: 13 | C32: Event loop, call stack, microtasks vs macrotasks | E32: 3.9 | H32: Not started | I32: 0
... A37: 02 ⚡ JavaScript Deep Dive | B37: 18 | C37: Deploy all 3 + write READMEs with screenshots | E37: 3.9 | H37: Not started | I37: 0
A38: 03 🔥 React + TypeScript + Tailwind | B38: 1 | C38: Create a React app with Vite (`npm create vite@latest`) | D38: Hitesh Choudhary (chai aur code) — Chai aur React | E38: 5 | H38: Not started | I38: 0
A39: 03 🔥 React + TypeScript + Tailwind | B39: 2 | C39: JSX rules + conditional rendering + fragments | E39: 5 | H39: Not started | I39: 0
A40: 03 🔥 React + TypeScript + Tailwind | B40: 3 | C40: Components, props, children, composition | E40: 5 | H40: Not started | I40: 0
A41: 03 🔥 React + TypeScript + Tailwind | B41: 4 | C41: useState + controlled inputs + forms | E41: 5 | H41: Not started | I41: 0
A42: 03 🔥 React + TypeScript + Tailwind | B42: 5 | C42: Lists & keys — and why index keys break things | E42: 5 | H42: Not started | I42: 0
A43: 03 🔥 React + TypeScript + Tailwind | B43: 6 | C43: useEffect: dependency array, cleanup, avoid loops | E43: 5 | H43: Not started | I43: 0
A44: 03 🔥 React + TypeScript + Tailwind | B44: 7 | C44: Lifting state up + derived state (no duplicate state) | E44: 5 | H44: Not started | I44: 0
A45: 03 🔥 React + TypeScript + Tailwind | B45: 8 | C45: React Router: routes, params, nested routes, 404 | E45: 5 | H45: Not started | I45: 0
A46: 03 🔥 React + TypeScript + Tailwind | B46: 9 | C46: Context API + custom hooks | E46: 5 | H46: Not started | I46: 0
...

Sheet WEEKLY LOG
A1: WEEKLY LOG
A2: 32 weeks, pre-dated from Mon 19 Oct 2026. Fill this every Sunday — 10 minutes, honestly.
A3: Week | B3: Week of (Mon) | C3: Planned focus | D3: Target hrs | E3: Hours logged | F3: DSA problems | G3: Lessons / videos | H3: Biggest win | I3: Blocker & fix | J3: Energy 1–5
A4: 1 | B4: 46314 | C4: 01 🎮 — Setup, Git & HTML/CSS Pro | D4: 30
A5: 2 | B5: 46321 | C5: 01 🎮 — Setup, Git & HTML/CSS Pro | D5: 30
A6: 3 | B6: 46328 | C6: 02 ⚡ — JavaScript Deep Dive | D6: 30
A7: 4 | B7: 46335 | C7: 02 ⚡ — JavaScript Deep Dive | D7: 30
A8: 5 | B8: 46342 | C8: 02 ⚡ — JavaScript Deep Dive | D8: 30
A9: 6 | B9: 46349 | C9: 02 ⚡ — JavaScript Deep Dive | D9: 30
A10: 7 | B10: 46356 | C10: 02 ⚡ — JavaScript Deep Dive | D10: 30
A11: 8 | B11: 46363 | C11: 03 🔥 — React + TypeScript + Tailwind | D11: 30
A12: 9 | B12: 46370 | C12: 03 🔥 — React + TypeScript + Tailwind | D12: 30
A13: 10 | B13: 46377 | C13: 03 🔥 — React + TypeScript + Tailwind | D13: 30
A14: 11 | B14: 46384 | C14: 03 🔥 — React + TypeScript + Tailwind | D14: 30
A15: 12 | B15: 46391 | C15: 04 🏰 — Node.js + Express + MongoDB | D15: 30
... A35: 32 | B35: 46531 | C35: 09 🏁 — Portfolio, Resume & Offers | D35: 30
A36: Σ | C36: Totals | D36: =SUM(D4:D35) | E36: =SUM(E4:E35) | F36: =SUM(F4:F35) | G36: =SUM(G4:G35)

Sheet PROJECTS
A1: PROJECTS — the boss ladder
A2: A project is only 'done' when it is deployed and the README has a live link. Milestones: 1 = not started, 2 = in progress, 3 = done.
A3: Project | B3: Stack | C3: Weeks | D3: Milestones to hit | E3: Live URL | F3: GitHub repo | G3: Demo video | H3: README done? | I3: Status
A4: LV.1 Kerala Travel Planner | B4: HTML · CSS · JS · API · localStorage | C4: Week 4–5 | D4: Search destinations • Filter by district • Save favourites • Fully responsive | H4: Not yet | I4: Not started
A5: LV.2 Expense Tracker (React + TS) | B5: React · TypeScript · Tailwind · Recharts | C5: Week 10–11 | D5: Add/edit/delete expenses • Category charts • Monthly filters • Local persistence | H5: Not yet | I5: Not started
A6: LV.3 Job Board API | B6: Node · Express · MongoDB · JWT | C6: Week 15–16 | D6: Auth + roles • CRUD jobs • Search + pagination • Rate limiting | H6: Not yet | I6: Not started
A7: LV.4 SkillBridge (Capstone) | B7: MERN · TypeScript · Docker · CI/CD | C7: Week 19–22 | D7: Student & recruiter roles • Job posts + applications • Dashboard analytics • Dockerised + CI | H7: Not yet | I7: Not started
A8: LV.5 Kerala IT Job Market Analyser | B8: Python · pandas · Power BI · React | C8: Week 23–24 | D8: Scrape job boards • Skill frequency analysis • Salary bands • Power BI dashboard | H8: Not yet | I8: Not started

Sheet DSA LOG
A1: DSA LOG
A2: 150 slots. 45 minutes a day from week 3. Patterns pre-filled; the first 30 rows have starter problems.
A3: # | B3: Pattern | C3: Problem | D3: Platform | E3: Difficulty | F3: Status | G3: Time (min) | H3: Date solved | I3: Re-solve date | J3: Notes / trick
A4: 1 | B4: Arrays & running sum | C4: Running Sum of 1d Array | D4: LeetCode | E4: Easy | F4: Not started
A5: 2 | B5: Arrays & running sum | C5: Best Time to Buy and Sell Stock | D5: LeetCode | E5: Easy | F5: Not started
A6: 3 | B6: Arrays & running sum | C6: Maximum Subarray | D6: LeetCode | E6: Medium | F6: Not started
A7: 4 | B7: Strings & frequency counting | C7: Valid Anagram | D7: LeetCode | E7: Easy | F7: Not started
A8: 5 | B8: Strings & frequency counting | C8: Valid Palindrome | D8: LeetCode | E8: Easy | F8: Not started
A9: 6 | B9: Hashing (maps/sets) patterns | C9: Two Sum | D9: LeetCode | E9: Easy | F9: Not started
A10: 7 | B10: Hashing (maps/sets) patterns | C10: Contains Duplicate | D10: LeetCode | E10: Easy | F10: Not started
A11: 8 | B11: Hashing (maps/sets) patterns | C11: Group Anagrams | D11: LeetCode | E11: Medium | F11: Not started
A12: 9 | B12: Hashing (maps/sets) patterns | C12: Top K Frequent Elements | D12: LeetCode | E12: Medium | F12: Not started
A13: 10 | B13: Two pointers | C13: Two Sum II – Input Array Is Sorted | D13: LeetCode | E13: Medium | F13: Not started
A14: 11 | B14: Two pointers | C14: 3Sum | D14: LeetCode | E14: Medium | F14: Not started
A15: 12 | B15: Two pointers | C15: Container With Most Water | D15: LeetCode | E15: Medium | F15: Not started
... A33: 30 | B33: Dynamic programming intro (climbing stairs, knapsack) | C33: Climbing Stairs | D33: LeetCode | E33: Easy | F33: Not started
A34: 31 | B34: Arrays & running sum | F34: Not started
A35: 32 | B35: Strings & frequency counting | F35: Not started
A36: 33 | B36: Hashing (maps/sets) patterns | F36: Not started
A37: 34 | B37: Two pointers | F37: Not started
A38: 35 | B38: Sliding window | F38: Not started
A39: 36 | B39: Prefix sum | F39: Not started
A40: 37 | B40: Stack (valid parentheses, next greater element) | F40: Not started
A41: 38 | B41: Queue & deque basics | F41: Not started
A42: 39 | B42: Linked list (reverse, middle, cycle) | F42: Not started
A43: 40 | B43: Binary search (and binary search on answer) | F43: Not started
A44: 41 | B44: Sorting: bubble/selection/insertion + merge/quick idea | F44: Not started
A45: 42 | B45: Recursion & backtracking basics | F45: Not started
... A153: 150 | B153: Prefix sum | F153: Not started

Sheet JOB APPLICATIONS
A1: JOB APPLICATIONS
A2: Target: 25 per week from week 25. A follow-up after 5–7 days doubles your reply rate.
A3: Date | B3: Company | C3: Role | D3: Location | E3: Source | F3: Referral contact | G3: Status | H3: Next action | I3: Follow-up date | J3: Notes
A4: 46314 | B4: Example — Infopark company | C4: Full Stack Developer (Fresher) | D4: Kochi | E4: Infopark board | G4: Applied | H4: Follow up in 6 days | I4: 46321 | J4: Delete these example rows before you start.
G5: Not applied
G6: Not applied
G7: Not applied
G8: Not applied
G9: Not applied
G10: Not applied
G11: Not applied
G12: Not applied
G13: Not applied
G14: Not applied
G15: Not applied
G16: Not applied
... G203: Not applied

Sheet INTERVIEW PREP
A1: INTERVIEW PREP
A2: Answer out loud first, then write the short version here. Revise the low-confidence ones weekly.
A3: Topic | B3: # | C3: Question | D3: Your answer (short version) | E3: Example from your projects | F3: Confidence 1–5 | G3: Last revised
A4: JavaScript | B4: 1 | C4: What is a closure? Give a real use case. | F4: 0
A5: JavaScript | B5: 2 | C5: Difference between var, let and const, including hoisting and TDZ. | F5: 0
A6: JavaScript | B6: 3 | C6: Explain the event loop with a setTimeout + Promise example. | F6: 0
A7: JavaScript | B7: 4 | C7: Implement debounce and throttle. | F7: 0
A8: JavaScript | B8: 5 | C8: map vs forEach vs filter vs reduce — when do you use each? | F8: 0
A9: JavaScript | B9: 6 | C9: Explain `this` in arrow functions vs regular functions. | F9: 0
A10: JavaScript | B10: 7 | C10: Shallow vs deep copy — write a deep clone. | F10: 0
A11: JavaScript | B11: 8 | C11: What is event delegation and why is it useful? | F11: 0
A12: JavaScript | B12: 9 | C12: Explain promises vs async/await and error handling. | F12: 0
A13: JavaScript | B13: 10 | C13: Curry a function: sum(1)(2)(3). | F13: 0
A14: React | B14: 1 | C14: Why does React use keys? What breaks with index keys? | F14: 0
A15: React | B15: 2 | C15: Virtual DOM and reconciliation — explain simply. | F15: 0
... A43: HR / Behavioural | B43: 10 | C43: Do you have any questions for us? (Always yes: team, code review, learning budget.) | F43: 0

Sheet RESOURCES
A1: RESOURCES
A2: Every link verified when the roadmap was built (Oct 2026). If a video link dies, search the channel name.
A3: Season | B3: Type | C3: Resource | D3: Channel / site | E3: Link
A4: 01 🎮 Setup, Git & HTML/CSS Pro | B4: Video/Docs | C4: Complete Git and GitHub Tutorial | D4: Kunal Kushwaha | E4: https://www.youtube.com/watch?v=apGV9Kg7ics
A5: 01 🎮 Setup, Git & HTML/CSS Pro | B5: Video/Docs | C5: HTML & CSS Full Course – Beginner to Pro | D5: SuperSimpleDev | E5: https://www.youtube.com/watch?v=G3e-cpL7ofc
A6: 01 🎮 Setup, Git & HTML/CSS Pro | B6: Video/Docs | C6: Frontend Roadmap (read, don't binge) | D6: roadmap.sh | E6: https://roadmap.sh/frontend
A7: 02 ⚡ JavaScript Deep Dive | B7: Video/Docs | C7: JavaScript Tutorial Full Course – Beginner to Pro (2024) | D7: SuperSimpleDev | E7: https://www.youtube.com/watch?v=EerdGm-ehJQ
A8: 02 ⚡ JavaScript Deep Dive | B8: Video/Docs | C8: Namaste JavaScript (Season 1 + 2) | D8: Akshay Saini | E8: https://www.youtube.com/playlist?list=PLlasXeu85E9cQ32gLCvAvr9vNaUccPVNP
A9: 02 ⚡ JavaScript Deep Dive | B9: Video/Docs | C9: The Modern JavaScript Tutorial | D9: javascript.info | E9: https://javascript.info
A10: 03 🔥 React + TypeScript + Tailwind | B10: Video/Docs | C10: Chai aur React | D10: Hitesh Choudhary (chai aur code) | E10: https://www.youtube.com/playlist?list=PLu71SKxNbfoDqgPchmvIsL4hTnJIrtige
A11: 03 🔥 React + TypeScript + Tailwind | B11: Video/Docs | C11: TypeScript playlist | D11: Hitesh Choudhary | E11: https://www.youtube.com/playlist?list=PLRAV69dS1uWRPSfKzwZsIm-Axxq-LxqhW
A12: 03 🔥 React + TypeScript + Tailwind | B12: Video/Docs | C12: Learn React (official docs) | D12: react.dev | E12: https://react.dev/learn
A13: 03 🔥 React + TypeScript + Tailwind | B13: Video/Docs | C13: Tailwind CSS docs | D13: tailwindcss.com | E13: https://tailwindcss.com/docs
A14: 04 🏰 Node.js + Express + MongoDB | B14: Video/Docs | C14: Complete Backend Developer Course (chai aur backend) | D14: Hitesh Choudhary | E14: https://www.youtube.com/watch?v=7fjOw8ApZ1I
... A57: Cheat sheet | B57: Web | C57: Full-stack roadmap | D57: Your map when you feel lost. | E57: https://roadmap.sh/full-stack

Sheet CHEAT SHEET
A1: CHEAT SHEET
A2: Print this tab (Ctrl+P) and stick it next to your monitor.
B4: GIT — daily commands
B5: Command | C5: What it does
B6: git init | C6: Start a repo
B7: git status | C7: What changed?
B8: git add . | C8: Stage everything
B9: git commit -m "feat: add login" | C9: Commit with a meaningful message
B10: git branch -M main | C10: Rename branch to main
B11: git remote add origin <url> | C11: Connect to GitHub
B12: git push -u origin main | C12: First push
B13: git checkout -b feature/auth | C13: New branch
B14: git merge feature/auth | C14: Merge into current branch
B15: git pull --rebase | C15: Sync cleanly
B16: git stash / git stash pop | C16: Park work temporarily
... B19: git clone <url> | C19: Copy a repo locally
B21: VS CODE — 15 shortcuts
B22: Shortcut | C22: Action
B23: Ctrl + P | C23: Quick open file
B24: Ctrl + Shift + P | C24: Command palette (the cheat code for everything)
B25: Ctrl + ` | C25: Toggle terminal
B26: Ctrl + B | C26: Toggle sidebar
B27: Ctrl + D | C27: Select next occurrence (multi-cursor)
B28: Ctrl + Shift + L | C28: Select all occurrences
B29: Alt + ↑ / ↓ | C29: Move line up / down
B30: Shift + Alt + ↓ | C30: Duplicate line
B31: Ctrl + Shift + K | C31: Delete line
B32: F2 | C32: Rename symbol everywhere
B33: Ctrl + / | C33: Toggle comment
... B37: Ctrl + Shift + V | C37: Markdown preview
B39: JAVASCRIPT — array & object methods
B40: Method | C40: What it does
B41: map() | C41: Transform every item → new array
B42: filter() | C42: Keep items that pass a test
B43: reduce() | C43: Boil an array down to one value
B44: find() | C44: First matching item
B45: some() / every() | C45: Any match? / All match?
B46: sort() | C46: Sort (mutates — copy first)
B47: flatMap() | C47: Map + flatten one level
B48: Object.entries() | C48: Object → [key, value] pairs
...

Sheet SKILLS
A1: SKILLS MATRIX
A2: Rate yourself 1–5 now and set a target. Evidence = the project or link that proves it.
A3: Skill / tool | B3: Why it matters | C3: Priority | D3: Now 1–5 | E3: Target 1–5 | F3: Evidence (project / link) | G3: Notes
A4: HTML / CSS | B4: Every JD. Your foundation. Don't skip responsive + accessibility. | C4: MUST | D4: 1 | E4: 4 | G4: Planned: Week 1–2
A5: JavaScript (ES6+) | B5: The #1 interview filter in India. Closures, async, array methods. | C5: MUST | D5: 1 | E5: 4 | G5: Planned: Week 3–7
A6: React | B6: ~70% of frontend JDs list React as primary framework. | C6: MUST | D6: 1 | E6: 4 | G6: Planned: Week 8–11
A7: TypeScript | B7: Expected in most new product-company codebases; +25–40% pay premium. | C7: MUST | D7: 1 | E7: 4 | G7: Planned: Week 8–11
A8: Git & GitHub | B8: Non-negotiable. Your green squares are your proof of work. | C8: MUST | D8: 1 | E8: 4 | G8: Planned: Week 1
A9: Node.js + Express | B9: The 'backend' half of MERN; most common fresher full-stack stack. | C9: MUST | D9: 1 | E9: 4 | G9: Planned: Week 12–16
A10: MongoDB / Mongoose | B10: Default database for MERN projects and startups. | C10: MUST | D10: 1 | E10: 4 | G10: Planned: Week 12–16
A11: SQL (MySQL/Postgres) | B11: Half of enterprise JDs still ask for SQL. Learn joins + indexes. | C11: MUST | D11: 1 | E11: 4 | G11: Planned: Week 17–18
A12: REST APIs + Postman | B12: You will be asked to 'explain your API' in every backend round. | C12: MUST | D12: 1 | E12: 4 | G12: Planned: Week 12–16
A13: Tailwind CSS | B13: Fast UI, common in startup codebases, great for portfolio speed. | C13: SHOULD | D13: 1 | E13: 4 | G13: Planned: Week 8–11
A14: Docker | B14: 20–40% salary premium skillset; small teams love devs who can ship. | C14: SHOULD | D14: 1 | E14: 4 | G14: Planned: Week 19–22
A15: Cloud deployment (Vercel/Render/AWS basics) | B15: A live URL beats a screenshot. Recruiters check. | C15: SHOULD | D15: 1 | E15: 4 | G15: Planned: Week 19–22
... A21: Kubernetes | B21: Not a fresher requirement. Ignore for now. | C21: LATER | D21: 1 | E21: 4 | G21: Planned: Year 2+

Sheet LISTS
A2: Arrays & running sum | B2: LeetCode
A3: Strings & frequency counting | B3: HackerRank
A4: Hashing (maps/sets) patterns | B4: GeeksforGeeks
A5: Two pointers | B5: CodeChef
A6: Sliding window | B6: Other
A7: Prefix sum
A8: Stack (valid parentheses, next greater element)
A9: Queue & deque basics
A10: Linked list (reverse, middle, cycle)
A11: Binary search (and binary search on answer)
A12: Sorting: bubble/selection/insertion + merge/quick idea
A13: Recursion & backtracking basics
A14: Trees: traversals, height, diameter
A15: BST basics
A16: Heaps / priority queue basics
A17: Graphs: BFS, DFS, connected components
A18: Greedy basics
... A20: Bit manipulation basics
